Server listening on port 8080
Traceback (most recent call last):
  File "server.py", line 45, in <module>
    asyncio.get_event_loop().run_until_complete(start_server)
  File "/usr/lib/python3.7/asyncio/base_events.py", line 587, in run_until_complete
    return future.result()
  File "/usr/lib/python3.7/asyncio/tasks.py", line 630, in _wrap_awaitable
    return (yield from awaitable.__await__())
  File "/home/ubuntu/.local/lib/python3.7/site-packages/websockets/legacy/server.py", line 1042, in __await_impl__
    server = await self._create_server()
  File "/usr/lib/python3.7/asyncio/base_events.py", line 1389, in create_server
    % (sa, err.strerror.lower())) from None
OSError: [Errno 98] error while attempting to bind on address ('0.0.0.0', 8080): address already in use
Server listening on port 8080
Traceback (most recent call last):
  File "server.py", line 45, in <module>
    asyncio.get_event_loop().run_until_complete(start_server)
  File "/usr/lib/python3.7/asyncio/base_events.py", line 587, in run_until_complete
    return future.result()
  File "/usr/lib/python3.7/asyncio/tasks.py", line 630, in _wrap_awaitable
    return (yield from awaitable.__await__())
  File "/home/ubuntu/.local/lib/python3.7/site-packages/websockets/legacy/server.py", line 1042, in __await_impl__
    server = await self._create_server()
  File "/usr/lib/python3.7/asyncio/base_events.py", line 1389, in create_server
    % (sa, err.strerror.lower())) from None
OSError: [Errno 98] error while attempting to bind on address ('0.0.0.0', 8080): address already in use
Server listening on port 8080
Traceback (most recent call last):
  File "server.py", line 45, in <module>
    asyncio.get_event_loop().run_until_complete(start_server)
  File "/usr/lib/python3.7/asyncio/base_events.py", line 587, in run_until_complete
    return future.result()
  File "/usr/lib/python3.7/asyncio/tasks.py", line 630, in _wrap_awaitable
    return (yield from awaitable.__await__())
  File "/home/ubuntu/.local/lib/python3.7/site-packages/websockets/legacy/server.py", line 1042, in __await_impl__
    server = await self._create_server()
  File "/usr/lib/python3.7/asyncio/base_events.py", line 1389, in create_server
    % (sa, err.strerror.lower())) from None
OSError: [Errno 98] error while attempting to bind on address ('0.0.0.0', 8080): address already in use
Server listening on port 8080
Traceback (most recent call last):
  File "server.py", line 45, in <module>
    asyncio.get_event_loop().run_until_complete(start_server)
  File "/usr/lib/python3.7/asyncio/base_events.py", line 587, in run_until_complete
    return future.result()
  File "/usr/lib/python3.7/asyncio/tasks.py", line 630, in _wrap_awaitable
    return (yield from awaitable.__await__())
  File "/home/ubuntu/.local/lib/python3.7/site-packages/websockets/legacy/server.py", line 1042, in __await_impl__
    server = await self._create_server()
  File "/usr/lib/python3.7/asyncio/base_events.py", line 1389, in create_server
    % (sa, err.strerror.lower())) from None
OSError: [Errno 98] error while attempting to bind on address ('0.0.0.0', 8080): address already in use
